<?xml version="1.0"?>
<robot name="robo_cayote" xmlns:xacro="http://ros.org/wiki/xacro">
  <link name="base_link">
    <visual>
      <origin xyz="0 0.14 0" rpy="0 0 0"/>
      <geometry>
        <box size="0.84 0.06 0.4359"/>
      </geometry>
    </visual>
    <collision>
      <origin xyz="0 0.14 0" rpy="0 0 0"/>
      <geometry>
        <box size="0.84 0.06 0.4359"/>
      </geometry>
    </collision>
  </link>
  <joint name="sliderjoint" type="prismatic">
    <parent link="base_link"/>
    <child link="solid"/>
    <axis xyz="0 1 0"/>
    <limit lower="-0.1" upper="0.1" effort="10" velocity="10"/>
    <origin xyz="0.31 0.02 -0.28" rpy="0 0 0"/>
  </joint>
  <link name="solid">
  </link>
  <joint name="steer_motor_fr" type="continuous">
    <parent link="solid"/>
    <child link="solid_0"/>
    <axis xyz="0 1 0"/>
    <limit effort="5" velocity="10"/>
    <origin xyz="0 0 0" rpy="0 0 0"/>
  </joint>
  <link name="solid_0">
  </link>
  <joint name="wheel_motor_fr" type="continuous">
    <parent link="solid_0"/>
    <child link="solid_1"/>
    <axis xyz="0 0 1"/>
    <limit effort="20" velocity="10"/>
    <origin xyz="0 0 0" rpy="0 0 0"/>
  </joint>
  <link name="solid_1">
    <visual>
      <origin xyz="0 0 0" rpy="0 0 0"/>
      <geometry>
        <cylinder radius="0.06" length="0.05"/>
      </geometry>
    </visual>
    <collision>
      <origin xyz="0 0 0" rpy="0 0 0"/>
      <geometry>
        <cylinder radius="0.06" length="0.05"/>
      </geometry>
    </collision>
  </link>
  <link name="appearance">
  </link>
  <joint name="solid_1_appearance_joint" type="fixed">
    <parent link="solid_1"/>
    <child link="appearance"/>
    <origin xyz="0 0 0" rpy="0 0 0"/>
  </joint>
  <joint name="sliderjoint_2" type="prismatic">
    <parent link="base_link"/>
    <child link="solid_3"/>
    <axis xyz="0 1 0"/>
    <limit lower="-0.1" upper="0.1" effort="10" velocity="10"/>
    <origin xyz="0.31 0.02 0.28" rpy="0 0 0"/>
  </joint>
  <link name="solid_3">
  </link>
  <joint name="steer_motor_fl" type="continuous">
    <parent link="solid_3"/>
    <child link="solid_4"/>
    <axis xyz="0 1 0"/>
    <limit effort="5" velocity="10"/>
    <origin xyz="0 0 0" rpy="0 0 0"/>
  </joint>
  <link name="solid_4">
  </link>
  <joint name="wheel_motor_fl" type="continuous">
    <parent link="solid_4"/>
    <child link="solid_5"/>
    <axis xyz="0 0 1"/>
    <limit effort="20" velocity="10"/>
    <origin xyz="0 0 0" rpy="0 0 0"/>
  </joint>
  <link name="solid_5">
    <visual>
      <origin xyz="0 0 0" rpy="0 0 0"/>
      <geometry>
        <cylinder radius="0.06" length="0.05"/>
      </geometry>
    </visual>
    <collision>
      <origin xyz="0 0 0" rpy="0 0 0"/>
      <geometry>
        <cylinder radius="0.06" length="0.05"/>
      </geometry>
    </collision>
  </link>
  <link name="appearance_6">
  </link>
  <joint name="solid_5_appearance_6_joint" type="fixed">
    <parent link="solid_5"/>
    <child link="appearance_6"/>
    <origin xyz="0 0 0" rpy="0 0 0"/>
  </joint>
  <joint name="sliderjoint_7" type="prismatic">
    <parent link="base_link"/>
    <child link="solid_8"/>
    <axis xyz="0 1 0"/>
    <limit lower="-0.1" upper="0.1" effort="10" velocity="10"/>
    <origin xyz="-0.31 0.02 -0.28" rpy="0 0 0"/>
  </joint>
  <link name="solid_8">
  </link>
  <joint name="wheel_motor_rr" type="continuous">
    <parent link="solid_8"/>
    <child link="solid_9"/>
    <axis xyz="0 0 1"/>
    <limit effort="20" velocity="10"/>
    <origin xyz="0 0 0" rpy="0 0 0"/>
  </joint>
  <link name="solid_9">
    <visual>
      <origin xyz="0 0 0" rpy="0 0 0"/>
      <geometry>
        <cylinder radius="0.06" length="0.05"/>
      </geometry>
    </visual>
    <collision>
      <origin xyz="0 0 0" rpy="0 0 0"/>
      <geometry>
        <cylinder radius="0.06" length="0.05"/>
      </geometry>
    </collision>
  </link>
  <link name="appearance_10">
  </link>
  <joint name="solid_9_appearance_10_joint" type="fixed">
    <parent link="solid_9"/>
    <child link="appearance_10"/>
    <origin xyz="0 0 0" rpy="0 0 0"/>
  </joint>
  <joint name="sliderjoint_11" type="prismatic">
    <parent link="base_link"/>
    <child link="solid_12"/>
    <axis xyz="0 1 0"/>
    <limit lower="-0.1" upper="0.1" effort="10" velocity="10"/>
    <origin xyz="-0.31 0.02 0.28" rpy="0 0 0"/>
  </joint>
  <link name="solid_12">
  </link>
  <joint name="wheel_motor_rl" type="continuous">
    <parent link="solid_12"/>
    <child link="solid_13"/>
    <axis xyz="0 0 1"/>
    <limit effort="20" velocity="10"/>
    <origin xyz="0 0 0" rpy="0 0 0"/>
  </joint>
  <link name="solid_13">
    <visual>
      <origin xyz="0 0 0" rpy="0 0 0"/>
      <geometry>
        <cylinder radius="0.06" length="0.05"/>
      </geometry>
    </visual>
    <collision>
      <origin xyz="0 0 0" rpy="0 0 0"/>
      <geometry>
        <cylinder radius="0.06" length="0.05"/>
      </geometry>
    </collision>
  </link>
  <link name="appearance_14">
  </link>
  <joint name="solid_13_appearance_14_joint" type="fixed">
    <parent link="solid_13"/>
    <child link="appearance_14"/>
    <origin xyz="0 0 0" rpy="0 0 0"/>
  </joint>
  <link name="sonar_front_right">
  </link>
  <joint name="base_link_sonar_front_right_joint" type="fixed">
    <parent link="base_link"/>
    <child link="sonar_front_right"/>
    <origin xyz="0.33 0.05 -0.18" rpy="3.141593 1.570793 3.141593"/>
  </joint>
  <link name="sonar_front_left">
  </link>
  <joint name="base_link_sonar_front_left_joint" type="fixed">
    <parent link="base_link"/>
    <child link="sonar_front_left"/>
    <origin xyz="0.33 0.05 0.18" rpy="3.141593 1.570793 3.141593"/>
  </joint>
  <link name="sonar_front_center">
  </link>
  <joint name="base_link_sonar_front_center_joint" type="fixed">
    <parent link="base_link"/>
    <child link="sonar_front_center"/>
    <origin xyz="0.38 0.05 0" rpy="3.141593 1.570793 3.141593"/>
  </joint>
  <link name="camera">
  </link>
  <joint name="base_link_camera_joint" type="fixed">
    <parent link="base_link"/>
    <child link="camera"/>
    <origin xyz="0 0.28 0" rpy="-1.570796 0 -1.570796"/>
  </joint>
  <link name="imu">
  </link>
  <joint name="base_link_imu_joint" type="fixed">
    <parent link="base_link"/>
    <child link="imu"/>
    <origin xyz="0 0 0" rpy="0 0 0"/>
  </joint>
  <link name="compass">
  </link>
  <joint name="base_link_compass_joint" type="fixed">
    <parent link="base_link"/>
    <child link="compass"/>
    <origin xyz="0 0 0" rpy="0 0 0"/>
  </joint>
  <link name="gps">
  </link>
  <joint name="base_link_gps_joint" type="fixed">
    <parent link="base_link"/>
    <child link="gps"/>
    <origin xyz="0 0 0" rpy="0 0 0"/>
  </joint>
  <link name="appearance_15">
  </link>
  <joint name="base_link_appearance_15_joint" type="fixed">
    <parent link="base_link"/>
    <child link="appearance_15"/>
    <origin xyz="0 0 0" rpy="0 0 0"/>
  </joint>
</robot>